<?xml version="1.0" encoding="utf-8"?>
<robot name="digit-v3">
	<link name="base">
		<inertial>
			<origin rpy="0.00000 -0.00000 0.00000" xyz="0.00164 0.00020 0.25955"/>
			<mass value="15.02839"/>
			<inertia ixx="0.42716" ixy="0" ixz="0" iyy="0.43686" iyz="0" izz="0.08554"/>
		</inertial>
		<collision>
			<origin rpy="0.00000 -0.00000 0.00000" xyz="0.00800 0.00000 0.21000"/>
			<geometry>
				<box size="0.19500 0.17400 0.49000"/>
			</geometry>
		</collision>
		<collision>
			<origin rpy="0.00000 -0.00000 0.00000" xyz="0.02000 0.00000 0.49000"/>
			<geometry>
				<cylinder length="0.06500" radius="0.05000"/>
			</geometry>
		</collision>
	</link>
	<link name="link1_2">
		<inertial>
			<origin rpy="0.00000 -0.00000 0.00000" xyz="0.00000 0.00000 0.00000"/>
			<mass value="0.00000"/>
			<inertia ixx="0.00000" ixy="0" ixz="0" iyy="0.00000" iyz="0" izz="0.00000"/>
		</inertial>
	</link>
	<link name="left-hip-roll">
		<inertial>
			<origin rpy="0.00000 -0.00000 0.00000" xyz="-0.00197 0.00024 0.03144"/>
			<mass value="0.91509"/>
			<inertia ixx="0.00000" ixy="0" ixz="0" iyy="0.00000" iyz="0" izz="0.00000"/>
		</inertial>
	</link>
	<link name="link1_4">
		<inertial>
			<origin rpy="0.00000 -0.00000 0.00000" xyz="0.00000 0.00000 0.00000"/>
			<mass value="0.00000"/>
			<inertia ixx="0.00000" ixy="0" ixz="0" iyy="0.00000" iyz="0" izz="0.00000"/>
		</inertial>
	</link>
	<link name="left-hip-yaw">
		<inertial>
			<origin rpy="0.00000 -0.00000 0.00000" xyz="0.00001 -0.00195 0.04203"/>
			<mass value="0.81875"/>
			<inertia ixx="0.00000" ixy="0" ixz="0" iyy="0.00000" iyz="0" izz="0.00000"/>
		</inertial>
	</link>
	<link name="link1_6">
		<inertial>
			<origin rpy="0.00000 -0.00000 0.00000" xyz="0.00000 0.00000 0.00000"/>
			<mass value="0.00000"/>
			<inertia ixx="0.00000" ixy="0" ixz="0" iyy="0.00000" iyz="0" izz="0.00000"/>
		</inertial>
	</link>
	<link name="left-hip-pitch">
		<inertial>
			<origin rpy="0.00000 -0.00000 0.00000" xyz="0.06054 0.00052 -0.03886"/>
			<mass value="6.24428"/>
			<inertia ixx="0.01599" ixy="0" ixz="0" iyy="0.03598" iyz="0" izz="0.03039"/>
		</inertial>
		<collision>
			<origin rpy="0.00000 -0.00000 0.00000" xyz="0.00000 0.00000 -0.04000"/>
			<geometry>
				<cylinder length="0.14400" radius="0.05000"/>
			</geometry>
		</collision>
		<collision>
			<origin rpy="0.00000 -0.00000 0.00000" xyz="0.12000 0.00000 -0.04000"/>
			<geometry>
				<cylinder length="0.14400" radius="0.05000"/>
			</geometry>
		</collision>
		<collision>
			<origin rpy="0.00000 -0.00000 0.00000" xyz="0.06000 0.00000 -0.04000"/>
			<geometry>
				<box size="0.12000 0.10000 0.14400"/>
			</geometry>
		</collision>
	</link>
	<link name="link1_10">
		<inertial>
			<origin rpy="0.00000 -0.00000 0.00000" xyz="0.00000 0.00000 0.00000"/>
			<mass value="0.00000"/>
			<inertia ixx="0.00000" ixy="0" ixz="0" iyy="0.00000" iyz="0" izz="0.00000"/>
		</inertial>
	</link>
	<link name="left-knee">
		<inertial>
			<origin rpy="0.00000 -0.00000 0.00000" xyz="0.04564 0.04215 0.00166"/>
			<mass value="1.22708"/>
			<inertia ixx="0.00000" ixy="0" ixz="0" iyy="0.00000" iyz="0" izz="0.00000"/>
		</inertial>
	</link>
	<link name="link1_12">
		<inertial>
			<origin rpy="0.00000 -0.00000 0.00000" xyz="0.00000 0.00000 0.00000"/>
			<mass value="0.00000"/>
			<inertia ixx="0.00000" ixy="0" ixz="0" iyy="0.00000" iyz="0" izz="0.00000"/>
		</inertial>
	</link>
	<link name="left-shin">
		<inertial>
			<origin rpy="0.00000 -0.00000 0.00000" xyz="0.17426 0.01027 0.00107"/>
			<mass value="0.89579"/>
			<inertia ixx="0.00953" ixy="0" ixz="0" iyy="0.01134" iyz="0" izz="0.00330"/>
		</inertial>
		<collision>
			<origin rpy="0.00000 -0.00000 0.00000" xyz="0.23000 0.00000 0.00000"/>
			<geometry>
				<cylinder length="0.34300" radius="0.03000"/>
			</geometry>
		</collision>
		<collision>
			<origin rpy="0.00000 -0.00000 0.00000" xyz="0.12500 0.00900 0.00000"/>
			<geometry>
				<cylinder length="0.20000" radius="0.05000"/>
			</geometry>
		</collision>
	</link>
	<link name="link1_14">
		<inertial>
			<origin rpy="0.00000 -0.00000 0.00000" xyz="0.00000 0.00000 0.00000"/>
			<mass value="0.00000"/>
			<inertia ixx="0.00000" ixy="0" ixz="0" iyy="0.00000" iyz="0" izz="0.00000"/>
		</inertial>
	</link>
	<link name="left-tarsus">
		<inertial>
			<origin rpy="0.00000 -0.00000 0.00000" xyz="0.10078 -0.02918 0.00068"/>
			<mass value="1.32286"/>
			<inertia ixx="0.01781" ixy="0" ixz="0" iyy="0.01781" iyz="0" izz="0.00035"/>
		</inertial>
		<collision>
			<origin rpy="0.00000 -0.00000 0.00000" xyz="0.21000 -0.03000 0.00000"/>
			<geometry>
				<capsule length="0.36000" radius="0.02000"/>
			</geometry>
		</collision>
	</link>
	<link name="link1_16">
		<inertial>
			<origin rpy="0.00000 -0.00000 0.00000" xyz="0.00000 0.00000 0.00000"/>
			<mass value="0.00000"/>
			<inertia ixx="0.00000" ixy="0" ixz="0" iyy="0.00000" iyz="0" izz="0.00000"/>
		</inertial>
	</link>
	<link name="left-heel-spring">
		<inertial>
			<origin rpy="0.00000 -0.00000 0.00000" xyz="0.04909 0.00474 -0.00005"/>
			<mass value="0.23002"/>
			<inertia ixx="0.00000" ixy="0" ixz="0" iyy="0.00000" iyz="0" izz="0.00000"/>
		</inertial>
	</link>
	<link name="link1_18">
		<inertial>
			<origin rpy="0.00000 -0.00000 0.00000" xyz="0.00000 0.00000 0.00000"/>
			<mass value="0.00000"/>
			<inertia ixx="0.00000" ixy="0" ixz="0" iyy="0.00000" iyz="0" izz="0.00000"/>
		</inertial>
	</link>
	<link name="left-toe-A">
		<inertial>
			<origin rpy="0.00000 -0.00000 0.00000" xyz="0.00516 0.00000 -0.00225"/>
			<mass value="0.13956"/>
			<inertia ixx="0.00000" ixy="0" ixz="0" iyy="0.00000" iyz="0" izz="0.00000"/>
		</inertial>
	</link>
	<link name="link1_22">
		<inertial>
			<origin rpy="0.00000 -0.00000 0.00000" xyz="0.00000 0.00000 0.00000"/>
			<mass value="0.00000"/>
			<inertia ixx="0.00000" ixy="0" ixz="0" iyy="0.00000" iyz="0" izz="0.00000"/>
		</inertial>
	</link>
	<link name="left-toe-B">
		<inertial>
			<origin rpy="0.00000 -0.00000 0.00000" xyz="0.00516 0.00000 -0.00225"/>
			<mass value="0.13956"/>
			<inertia ixx="0.00000" ixy="0" ixz="0" iyy="0.00000" iyz="0" izz="0.00000"/>
		</inertial>
	</link>
	<link name="link1_26">
		<inertial>
			<origin rpy="0.00000 -0.00000 0.00000" xyz="0.00000 0.00000 0.00000"/>
			<mass value="0.00000"/>
			<inertia ixx="0.00000" ixy="0" ixz="0" iyy="0.00000" iyz="0" izz="0.00000"/>
		</inertial>
	</link>
	<link name="left-toe-pitch">
		<inertial>
			<origin rpy="0.00000 -0.00000 0.00000" xyz="-0.00014 0.00000 0.00000"/>
			<mass value="0.04388"/>
			<inertia ixx="0.00000" ixy="0" ixz="0" iyy="0.00000" iyz="0" izz="0.00000"/>
		</inertial>
	</link>
	<link name="link1_28">
		<inertial>
			<origin rpy="0.00000 -0.00000 0.00000" xyz="0.00000 0.00000 0.00000"/>
			<mass value="0.00000"/>
			<inertia ixx="0.00000" ixy="0" ixz="0" iyy="0.00000" iyz="0" izz="0.00000"/>
		</inertial>
	</link>
	<link name="left-toe-roll">
		<inertial>
			<origin rpy="0.00000 -0.00000 0.00000" xyz="0.00001 -0.02808 -0.02320"/>
			<mass value="0.53128"/>
			<inertia ixx="0.00247" ixy="0" ixz="0" iyy="0.00031" iyz="0" izz="0.00273"/>
		</inertial>
		<collision>
			<origin rpy="0.00000 -0.00000 0.00000" xyz="0.00000 -0.04370 -0.02550"/>
			<geometry>
				<box size="0.08000 0.23500 0.02300"/>
			</geometry>
		</collision>
	</link>
	<link name="link1_30">
		<inertial>
			<origin rpy="0.00000 -0.00000 0.00000" xyz="0.00000 0.00000 0.00000"/>
			<mass value="0.00000"/>
			<inertia ixx="0.00000" ixy="0" ixz="0" iyy="0.00000" iyz="0" izz="0.00000"/>
		</inertial>
	</link>
	<link name="left-shoulder-roll">
		<inertial>
			<origin rpy="0.00000 -0.00000 0.00000" xyz="-0.00082 -0.00316 0.02341"/>
			<mass value="0.53540"/>
			<inertia ixx="0.00000" ixy="0" ixz="0" iyy="0.00000" iyz="0" izz="0.00000"/>
		</inertial>
	</link>
	<link name="link1_32">
		<inertial>
			<origin rpy="0.00000 -0.00000 0.00000" xyz="0.00000 0.00000 0.00000"/>
			<mass value="0.00000"/>
			<inertia ixx="0.00000" ixy="0" ixz="0" iyy="0.00000" iyz="0" izz="0.00000"/>
		</inertial>
	</link>
	<link name="left-shoulder-pitch">
		<inertial>
			<origin rpy="0.00000 -0.00000 0.00000" xyz="-0.00004 -0.06188 -0.07379"/>
			<mass value="1.44036"/>
			<inertia ixx="0.00305" ixy="0" ixz="0" iyy="0.00305" iyz="0" izz="0.00139"/>
		</inertial>
		<collision>
			<origin rpy="0.00000 -0.00000 0.00000" xyz="0.00000 -0.09300 -0.10000"/>
			<geometry>
				<cylinder length="0.14000" radius="0.03800"/>
			</geometry>
		</collision>
	</link>
	<link name="link1_34">
		<inertial>
			<origin rpy="0.00000 -0.00000 0.00000" xyz="0.00000 0.00000 0.00000"/>
			<mass value="0.00000"/>
			<inertia ixx="0.00000" ixy="0" ixz="0" iyy="0.00000" iyz="0" izz="0.00000"/>
		</inertial>
	</link>
	<link name="left-shoulder-yaw">
		<inertial>
			<origin rpy="0.00000 -0.00000 0.00000" xyz="-0.00003 0.00194 0.11407"/>
			<mass value="1.06539"/>
			<inertia ixx="0.00406" ixy="0" ixz="0" iyy="0.00406" iyz="0" izz="0.00103"/>
		</inertial>
		<collision>
			<origin rpy="0.00000 -0.00000 0.00000" xyz="0.00000 0.00000 0.09256"/>
			<geometry>
				<cylinder length="0.13500" radius="0.03800"/>
			</geometry>
		</collision>
		<collision>
			<origin rpy="0.00000 -0.00000 0.00000" xyz="0.00000 -0.00350 0.18500"/>
			<geometry>
				<cylinder length="0.08000" radius="0.03000"/>
			</geometry>
		</collision>
	</link>
	<link name="link1_36">
		<inertial>
			<origin rpy="0.00000 -0.00000 0.00000" xyz="0.00000 0.00000 0.00000"/>
			<mass value="0.00000"/>
			<inertia ixx="0.00000" ixy="0" ixz="0" iyy="0.00000" iyz="0" izz="0.00000"/>
		</inertial>
	</link>
	<link name="left-elbow">
		<inertial>
			<origin rpy="0.00000 -0.00000 0.00000" xyz="0.10800 0.00052 -0.01777"/>
			<mass value="0.55058"/>
			<inertia ixx="0.00456" ixy="0" ixz="0" iyy="0.00678" iyz="0" izz="0.00236"/>
		</inertial>
		<collision>
			<origin rpy="0.00000 -0.00000 0.00000" xyz="0.18400 0.01000 -0.02600"/>
			<geometry>
				<cylinder length="0.31300" radius="0.01300"/>
			</geometry>
		</collision>
		<collision>
			<origin rpy="0.00000 -0.00000 0.00000" xyz="0.37937 0.00000 -0.06191"/>
			<geometry>
				<sphere radius="0.01500"/>
			</geometry>
		</collision>
	</link>
	<link name="link1_38">
		<inertial>
			<origin rpy="0.00000 -0.00000 0.00000" xyz="0.00000 0.00000 0.00000"/>
			<mass value="0.00000"/>
			<inertia ixx="0.00000" ixy="0" ixz="0" iyy="0.00000" iyz="0" izz="0.00000"/>
		</inertial>
	</link>
	<link name="right-hip-roll">
		<inertial>
			<origin rpy="0.00000 -0.00000 0.00000" xyz="-0.00197 -0.00024 0.03144"/>
			<mass value="0.91509"/>
			<inertia ixx="0.00000" ixy="0" ixz="0" iyy="0.00000" iyz="0" izz="0.00000"/>
		</inertial>
	</link>
	<link name="link1_40">
		<inertial>
			<origin rpy="0.00000 -0.00000 0.00000" xyz="0.00000 0.00000 0.00000"/>
			<mass value="0.00000"/>
			<inertia ixx="0.00000" ixy="0" ixz="0" iyy="0.00000" iyz="0" izz="0.00000"/>
		</inertial>
	</link>
	<link name="right-hip-yaw">
		<inertial>
			<origin rpy="0.00000 -0.00000 0.00000" xyz="0.00001 0.00195 0.04203"/>
			<mass value="0.81875"/>
			<inertia ixx="0.00000" ixy="0" ixz="0" iyy="0.00000" iyz="0" izz="0.00000"/>
		</inertial>
	</link>
	<link name="link1_42">
		<inertial>
			<origin rpy="0.00000 -0.00000 0.00000" xyz="0.00000 0.00000 0.00000"/>
			<mass value="0.00000"/>
			<inertia ixx="0.00000" ixy="0" ixz="0" iyy="0.00000" iyz="0" izz="0.00000"/>
		</inertial>
	</link>
	<link name="right-hip-pitch">
		<inertial>
			<origin rpy="0.00000 -0.00000 0.00000" xyz="0.06054 -0.00052 -0.03886"/>
			<mass value="6.24428"/>
			<inertia ixx="0.01599" ixy="0" ixz="0" iyy="0.03598" iyz="0" izz="0.03039"/>
		</inertial>
		<collision>
			<origin rpy="0.00000 -0.00000 0.00000" xyz="0.00000 0.00000 -0.04000"/>
			<geometry>
				<cylinder length="0.14400" radius="0.05000"/>
			</geometry>
		</collision>
		<collision>
			<origin rpy="0.00000 -0.00000 0.00000" xyz="0.12000 0.00000 -0.04000"/>
			<geometry>
				<cylinder length="0.14400" radius="0.05000"/>
			</geometry>
		</collision>
		<collision>
			<origin rpy="0.00000 -0.00000 0.00000" xyz="0.06000 0.00000 -0.04000"/>
			<geometry>
				<box size="0.12000 0.10000 0.14400"/>
			</geometry>
		</collision>
	</link>
	<link name="link1_46">
		<inertial>
			<origin rpy="0.00000 -0.00000 0.00000" xyz="0.00000 0.00000 0.00000"/>
			<mass value="0.00000"/>
			<inertia ixx="0.00000" ixy="0" ixz="0" iyy="0.00000" iyz="0" izz="0.00000"/>
		</inertial>
	</link>
	<link name="right-knee">
		<inertial>
			<origin rpy="0.00000 -0.00000 0.00000" xyz="0.04564 -0.04215 0.00166"/>
			<mass value="1.22708"/>
			<inertia ixx="0.00000" ixy="0" ixz="0" iyy="0.00000" iyz="0" izz="0.00000"/>
		</inertial>
	</link>
	<link name="link1_48">
		<inertial>
			<origin rpy="0.00000 -0.00000 0.00000" xyz="0.00000 0.00000 0.00000"/>
			<mass value="0.00000"/>
			<inertia ixx="0.00000" ixy="0" ixz="0" iyy="0.00000" iyz="0" izz="0.00000"/>
		</inertial>
	</link>
	<link name="right-shin">
		<inertial>
			<origin rpy="0.00000 -0.00000 0.00000" xyz="0.17426 -0.01027 0.00107"/>
			<mass value="0.89579"/>
			<inertia ixx="0.00953" ixy="0" ixz="0" iyy="0.01134" iyz="0" izz="0.00330"/>
		</inertial>
		<collision>
			<origin rpy="0.00000 -0.00000 0.00000" xyz="0.23000 0.00000 0.00000"/>
			<geometry>
				<cylinder length="0.34300" radius="0.03000"/>
			</geometry>
		</collision>
		<collision>
			<origin rpy="0.00000 -0.00000 0.00000" xyz="0.12500 -0.00900 0.00000"/>
			<geometry>
				<cylinder length="0.20000" radius="0.05000"/>
			</geometry>
		</collision>
	</link>
	<link name="link1_50">
		<inertial>
			<origin rpy="0.00000 -0.00000 0.00000" xyz="0.00000 0.00000 0.00000"/>
			<mass value="0.00000"/>
			<inertia ixx="0.00000" ixy="0" ixz="0" iyy="0.00000" iyz="0" izz="0.00000"/>
		</inertial>
	</link>
	<link name="right-tarsus">
		<inertial>
			<origin rpy="0.00000 -0.00000 0.00000" xyz="0.10078 0.02918 0.00068"/>
			<mass value="1.32286"/>
			<inertia ixx="0.01781" ixy="0" ixz="0" iyy="0.01781" iyz="0" izz="0.00035"/>
		</inertial>
		<collision>
			<origin rpy="0.00000 -0.00000 0.00000" xyz="0.21000 0.03000 0.00000"/>
			<geometry>
				<capsule length="0.36000" radius="0.02000"/>
			</geometry>
		</collision>
	</link>
	<link name="link1_52">
		<inertial>
			<origin rpy="0.00000 -0.00000 0.00000" xyz="0.00000 0.00000 0.00000"/>
			<mass value="0.00000"/>
			<inertia ixx="0.00000" ixy="0" ixz="0" iyy="0.00000" iyz="0" izz="0.00000"/>
		</inertial>
	</link>
	<link name="right-heel-spring">
		<inertial>
			<origin rpy="0.00000 -0.00000 0.00000" xyz="0.04909 -0.00474 -0.00005"/>
			<mass value="0.23002"/>
			<inertia ixx="0.00000" ixy="0" ixz="0" iyy="0.00000" iyz="0" izz="0.00000"/>
		</inertial>
	</link>
	<link name="link1_54">
		<inertial>
			<origin rpy="0.00000 -0.00000 0.00000" xyz="0.00000 0.00000 0.00000"/>
			<mass value="0.00000"/>
			<inertia ixx="0.00000" ixy="0" ixz="0" iyy="0.00000" iyz="0" izz="0.00000"/>
		</inertial>
	</link>
	<link name="right-toe-A">
		<inertial>
			<origin rpy="0.00000 -0.00000 0.00000" xyz="0.00516 -0.00000 -0.00225"/>
			<mass value="0.13956"/>
			<inertia ixx="0.00000" ixy="0" ixz="0" iyy="0.00000" iyz="0" izz="0.00000"/>
		</inertial>
	</link>
	<link name="link1_58">
		<inertial>
			<origin rpy="0.00000 -0.00000 0.00000" xyz="0.00000 0.00000 0.00000"/>
			<mass value="0.00000"/>
			<inertia ixx="0.00000" ixy="0" ixz="0" iyy="0.00000" iyz="0" izz="0.00000"/>
		</inertial>
	</link>
	<link name="right-toe-B">
		<inertial>
			<origin rpy="0.00000 -0.00000 0.00000" xyz="0.00516 -0.00000 -0.00225"/>
			<mass value="0.13956"/>
			<inertia ixx="0.00000" ixy="0" ixz="0" iyy="0.00000" iyz="0" izz="0.00000"/>
		</inertial>
	</link>
	<link name="link1_62">
		<inertial>
			<origin rpy="0.00000 -0.00000 0.00000" xyz="0.00000 0.00000 0.00000"/>
			<mass value="0.00000"/>
			<inertia ixx="0.00000" ixy="0" ixz="0" iyy="0.00000" iyz="0" izz="0.00000"/>
		</inertial>
	</link>
	<link name="right-toe-pitch">
		<inertial>
			<origin rpy="0.00000 -0.00000 0.00000" xyz="-0.00014 -0.00000 0.00000"/>
			<mass value="0.04388"/>
			<inertia ixx="0.00000" ixy="0" ixz="0" iyy="0.00000" iyz="0" izz="0.00000"/>
		</inertial>
	</link>
	<link name="link1_64">
		<inertial>
			<origin rpy="0.00000 -0.00000 0.00000" xyz="0.00000 0.00000 0.00000"/>
			<mass value="0.00000"/>
			<inertia ixx="0.00000" ixy="0" ixz="0" iyy="0.00000" iyz="0" izz="0.00000"/>
		</inertial>
	</link>
	<link name="right-toe-roll">
		<inertial>
			<origin rpy="0.00000 -0.00000 0.00000" xyz="0.00001 0.02808 -0.02320"/>
			<mass value="0.53128"/>
			<inertia ixx="0.00247" ixy="0" ixz="0" iyy="0.00031" iyz="0" izz="0.00273"/>
		</inertial>
		<collision>
			<origin rpy="0.00000 -0.00000 0.00000" xyz="0.00000 0.04370 -0.02550"/>
			<geometry>
				<box size="0.08000 0.23500 0.02300"/>
			</geometry>
		</collision>
	</link>
	<link name="link1_66">
		<inertial>
			<origin rpy="0.00000 -0.00000 0.00000" xyz="0.00000 0.00000 0.00000"/>
			<mass value="0.00000"/>
			<inertia ixx="0.00000" ixy="0" ixz="0" iyy="0.00000" iyz="0" izz="0.00000"/>
		</inertial>
	</link>
	<link name="right-shoulder-roll">
		<inertial>
			<origin rpy="0.00000 -0.00000 0.00000" xyz="-0.00082 0.00316 0.02341"/>
			<mass value="0.53540"/>
			<inertia ixx="0.00000" ixy="0" ixz="0" iyy="0.00000" iyz="0" izz="0.00000"/>
		</inertial>
	</link>
	<link name="link1_68">
		<inertial>
			<origin rpy="0.00000 -0.00000 0.00000" xyz="0.00000 0.00000 0.00000"/>
			<mass value="0.00000"/>
			<inertia ixx="0.00000" ixy="0" ixz="0" iyy="0.00000" iyz="0" izz="0.00000"/>
		</inertial>
	</link>
	<link name="right-shoulder-pitch">
		<inertial>
			<origin rpy="0.00000 -0.00000 0.00000" xyz="-0.00004 0.06188 -0.07379"/>
			<mass value="1.44036"/>
			<inertia ixx="0.00305" ixy="0" ixz="0" iyy="0.00305" iyz="0" izz="0.00139"/>
		</inertial>
		<collision>
			<origin rpy="0.00000 -0.00000 0.00000" xyz="0.00000 0.09300 -0.10000"/>
			<geometry>
				<cylinder length="0.14000" radius="0.03800"/>
			</geometry>
		</collision>
	</link>
	<link name="link1_70">
		<inertial>
			<origin rpy="0.00000 -0.00000 0.00000" xyz="0.00000 0.00000 0.00000"/>
			<mass value="0.00000"/>
			<inertia ixx="0.00000" ixy="0" ixz="0" iyy="0.00000" iyz="0" izz="0.00000"/>
		</inertial>
	</link>
	<link name="right-shoulder-yaw">
		<inertial>
			<origin rpy="0.00000 -0.00000 0.00000" xyz="-0.00003 -0.00194 0.11407"/>
			<mass value="1.06539"/>
			<inertia ixx="0.00406" ixy="0" ixz="0" iyy="0.00406" iyz="0" izz="0.00103"/>
		</inertial>
		<collision>
			<origin rpy="0.00000 -0.00000 0.00000" xyz="0.00000 0.00000 0.09256"/>
			<geometry>
				<cylinder length="0.13500" radius="0.03800"/>
			</geometry>
		</collision>
		<collision>
			<origin rpy="0.00000 -0.00000 0.00000" xyz="0.00000 -0.00350 0.18500"/>
			<geometry>
				<cylinder length="0.08000" radius="0.03000"/>
			</geometry>
		</collision>
	</link>
	<link name="link1_72">
		<inertial>
			<origin rpy="0.00000 -0.00000 0.00000" xyz="0.00000 0.00000 0.00000"/>
			<mass value="0.00000"/>
			<inertia ixx="0.00000" ixy="0" ixz="0" iyy="0.00000" iyz="0" izz="0.00000"/>
		</inertial>
	</link>
	<link name="right-elbow">
		<inertial>
			<origin rpy="0.00000 -0.00000 0.00000" xyz="0.10800 -0.00052 -0.01777"/>
			<mass value="0.55058"/>
			<inertia ixx="0.00456" ixy="0" ixz="0" iyy="0.00678" iyz="0" izz="0.00236"/>
		</inertial>
		<collision>
			<origin rpy="0.00000 -0.00000 0.00000" xyz="0.18400 0.01000 -0.02600"/>
			<geometry>
				<cylinder length="0.31300" radius="0.01300"/>
			</geometry>
		</collision>
		<collision>
			<origin rpy="0.00000 -0.00000 0.00000" xyz="0.37937 0.00000 -0.06191"/>
			<geometry>
				<sphere radius="0.01500"/>
			</geometry>
		</collision>
	</link>
	<joint name="left-hip-roll" type="revolute">
		<parent link="base"/>
		<child link="link1_2"/>
		<dynamics damping="1.0" friction="0.0001"/>
		<origin rpy="0.00000 -0.00000 0.00000" xyz="-0.00100 0.09100 0.00000"/>
		<axis xyz="0.00000 0.00000 1.00000"/>
	</joint>
	<joint name="jointfix_13_2" type="fixed">
		<parent link="link1_2"/>
		<child link="left-hip-roll"/>
		<dynamics damping="1.0" friction="0.0001"/>
		<origin rpy="0.00000 -0.00000 0.00000" xyz="0.00000 0.00000 0.00000"/>
		<axis xyz="0.00000 0.00000 0.00000"/>
	</joint>
	<joint name="left-hip-yaw" type="revolute">
		<parent link="left-hip-roll"/>
		<child link="link1_4"/>
		<dynamics damping="1.0" friction="0.0001"/>
		<origin rpy="0.00000 -0.00000 0.00000" xyz="-0.05050 0.00000 0.04400"/>
		<axis xyz="0.00000 0.00000 1.00000"/>
	</joint>
	<joint name="jointfix_12_4" type="fixed">
		<parent link="link1_4"/>
		<child link="left-hip-yaw"/>
		<dynamics damping="1.0" friction="0.0001"/>
		<origin rpy="0.00000 -0.00000 0.00000" xyz="0.00000 0.00000 0.00000"/>
		<axis xyz="0.00000 0.00000 0.00000"/>
	</joint>
	<joint name="left-hip-pitch" type="revolute">
		<parent link="left-hip-yaw"/>
		<child link="link1_6"/>
		<dynamics damping="1.0" friction="0.0001"/>
		<origin rpy="0.00000 -0.00000 0.00000" xyz="0.00000 0.00400 0.06800"/>
		<axis xyz="0.00000 0.00000 -1.00000"/>
	</joint>
	<joint name="jointfix_11_6" type="fixed">
		<parent link="link1_6"/>
		<child link="left-hip-pitch"/>
		<dynamics damping="1.0" friction="0.0001"/>
		<origin rpy="0.00000 -0.00000 0.00000" xyz="0.00000 0.00000 0.00000"/>
		<axis xyz="0.00000 0.00000 0.00000"/>
	</joint>
	<joint name="left-knee" type="revolute">
		<parent link="left-hip-pitch"/>
		<child link="link1_10"/>
		<dynamics damping="1.0" friction="0.0001"/>
		<origin rpy="0.00000 -0.00000 0.00000" xyz="0.12000 0.00000 0.00450"/>
		<axis xyz="0.00000 0.00000 1.00000"/>
	</joint>
	<joint name="jointfix_10_10" type="fixed">
		<parent link="link1_10"/>
		<child link="left-knee"/>
		<dynamics damping="1.0" friction="0.0001"/>
		<origin rpy="0.00000 -0.00000 0.00000" xyz="0.00000 0.00000 0.00000"/>
		<axis xyz="0.00000 0.00000 0.00000"/>
	</joint>
	<joint name="left-shin" type="continuous">
		<parent link="left-knee"/>
		<child link="link1_12"/>
		<dynamics damping="1.0" friction="0.0001"/>
		<origin rpy="0.00000 -0.00000 0.00000" xyz="0.06068 0.04741 0.00000"/>
		<axis xyz="0.00000 0.00000 1.00000"/>
	</joint>
	<joint name="jointfix_9_12" type="fixed">
		<parent link="link1_12"/>
		<child link="left-shin"/>
		<dynamics damping="1.0" friction="0.0001"/>
		<origin rpy="0.00000 -0.00000 0.00000" xyz="0.00000 0.00000 0.00000"/>
		<axis xyz="0.00000 0.00000 0.00000"/>
	</joint>
	<joint name="left-tarsus" type="revolute">
		<parent link="left-shin"/>
		<child link="link1_14"/>
		<dynamics damping="1.0" friction="0.0001"/>
		<origin rpy="0.00000 -0.00000 0.00000" xyz="0.43476 0.02000 0.00000"/>
		<axis xyz="0.00000 0.00000 1.00000"/>
	</joint>
	<joint name="jointfix_8_14" type="fixed">
		<parent link="link1_14"/>
		<child link="left-tarsus"/>
		<dynamics damping="1.0" friction="0.0001"/>
		<origin rpy="0.00000 -0.00000 0.00000" xyz="0.00000 0.00000 0.00000"/>
		<axis xyz="0.00000 0.00000 0.00000"/>
	</joint>
	<joint name="left-heel-spring" type="revolute">
		<parent link="left-tarsus"/>
		<child link="link1_16"/>
		<dynamics damping="1.0" friction="0.0001"/>
		<origin rpy="0.00000 -0.00000 0.00000" xyz="-0.01766 -0.02946 0.00104"/>
		<axis xyz="0.00000 0.00000 1.00000"/>
	</joint>
	<joint name="jointfix_1_16" type="fixed">
		<parent link="link1_16"/>
		<child link="left-heel-spring"/>
		<dynamics damping="1.0" friction="0.0001"/>
		<origin rpy="0.00000 -0.00000 0.00000" xyz="0.00000 0.00000 0.00000"/>
		<axis xyz="0.00000 0.00000 0.00000"/>
	</joint>
	<joint name="left-toe-A" type="revolute">
		<parent link="left-tarsus"/>
		<child link="link1_18"/>
		<dynamics damping="1.0" friction="0.0001"/>
		<origin rpy="0.00000 -0.00000 0.00000" xyz="0.05900 -0.03400 -0.02760"/>
		<axis xyz="0.00000 0.00000 1.00000"/>
	</joint>
	<joint name="jointfix_3_18" type="fixed">
		<parent link="link1_18"/>
		<child link="left-toe-A"/>
		<dynamics damping="1.0" friction="0.0001"/>
		<origin rpy="0.00000 -0.00000 0.00000" xyz="0.00000 0.00000 0.00000"/>
		<axis xyz="0.00000 0.00000 0.00000"/>
	</joint>
	<joint name="left-toe-B" type="revolute">
		<parent link="left-tarsus"/>
		<child link="link1_22"/>
		<dynamics damping="1.0" friction="0.0001"/>
		<origin rpy="0.00000 -0.00000 0.00000" xyz="0.11100 -0.03400 0.02760"/>
		<axis xyz="0.00000 0.00000 1.00000"/>
	</joint>
	<joint name="jointfix_5_22" type="fixed">
		<parent link="link1_22"/>
		<child link="left-toe-B"/>
		<dynamics damping="1.0" friction="0.0001"/>
		<origin rpy="0.00000 -0.00000 0.00000" xyz="0.00000 0.00000 0.00000"/>
		<axis xyz="0.00000 0.00000 0.00000"/>
	</joint>
	<joint name="left-toe-pitch" type="revolute">
		<parent link="left-tarsus"/>
		<child link="link1_26"/>
		<dynamics damping="1.0" friction="0.0001"/>
		<origin rpy="0.00000 -0.00000 0.00000" xyz="0.40800 -0.04000 0.00000"/>
		<axis xyz="0.00000 0.00000 1.00000"/>
	</joint>
	<joint name="jointfix_7_26" type="fixed">
		<parent link="link1_26"/>
		<child link="left-toe-pitch"/>
		<dynamics damping="1.0" friction="0.0001"/>
		<origin rpy="0.00000 -0.00000 0.00000" xyz="0.00000 0.00000 0.00000"/>
		<axis xyz="0.00000 0.00000 0.00000"/>
	</joint>
	<joint name="left-toe-roll" type="revolute">
		<parent link="left-toe-pitch"/>
		<child link="link1_28"/>
		<dynamics damping="1.0" friction="0.0001"/>
		<origin rpy="0.00000 -0.00000 0.00000" xyz="0.00000 0.00000 0.00000"/>
		<axis xyz="0.00000 0.00000 1.00000"/>
	</joint>
	<joint name="jointfix_6_28" type="fixed">
		<parent link="link1_28"/>
		<child link="left-toe-roll"/>
		<dynamics damping="1.0" friction="0.0001"/>
		<origin rpy="0.00000 -0.00000 0.00000" xyz="0.00000 0.00000 0.00000"/>
		<axis xyz="0.00000 0.00000 0.00000"/>
	</joint>
	<joint name="left-shoulder-roll" type="revolute">
		<parent link="base"/>
		<child link="link1_30"/>
		<dynamics damping="1.0" friction="0.0001"/>
		<origin rpy="0.00000 -0.00000 0.00000" xyz="-0.00100 0.12000 0.40000"/>
		<axis xyz="0.00000 0.00000 1.00000"/>
	</joint>
	<joint name="jointfix_17_30" type="fixed">
		<parent link="link1_30"/>
		<child link="left-shoulder-roll"/>
		<dynamics damping="1.0" friction="0.0001"/>
		<origin rpy="0.00000 -0.00000 0.00000" xyz="0.00000 0.00000 0.00000"/>
		<axis xyz="0.00000 0.00000 0.00000"/>
	</joint>
	<joint name="left-shoulder-pitch" type="revolute">
		<parent link="left-shoulder-roll"/>
		<child link="link1_32"/>
		<dynamics damping="1.0" friction="0.0001"/>
		<origin rpy="0.00000 -0.00000 0.00000" xyz="-0.00317 -0.01106 0.05550"/>
		<axis xyz="0.00000 0.00000 -1.00000"/>
	</joint>
	<joint name="jointfix_16_32" type="fixed">
		<parent link="link1_32"/>
		<child link="left-shoulder-pitch"/>
		<dynamics damping="1.0" friction="0.0001"/>
		<origin rpy="0.00000 -0.00000 0.00000" xyz="0.00000 0.00000 0.00000"/>
		<axis xyz="0.00000 0.00000 0.00000"/>
	</joint>
	<joint name="left-shoulder-yaw" type="revolute">
		<parent link="left-shoulder-pitch"/>
		<child link="link1_34"/>
		<dynamics damping="1.0" friction="0.0001"/>
		<origin rpy="0.00000 -0.00000 0.00000" xyz="0.00000 -0.16500 -0.10000"/>
		<axis xyz="0.00000 0.00000 1.00000"/>
	</joint>
	<joint name="jointfix_15_34" type="fixed">
		<parent link="link1_34"/>
		<child link="left-shoulder-yaw"/>
		<dynamics damping="1.0" friction="0.0001"/>
		<origin rpy="0.00000 -0.00000 0.00000" xyz="0.00000 0.00000 0.00000"/>
		<axis xyz="0.00000 0.00000 0.00000"/>
	</joint>
	<joint name="left-elbow" type="revolute">
		<parent link="left-shoulder-yaw"/>
		<child link="link1_36"/>
		<dynamics damping="1.0" friction="0.0001"/>
		<origin rpy="0.00000 -0.00000 0.00000" xyz="0.00000 -0.03850 0.18500"/>
		<axis xyz="0.00000 0.00000 1.00000"/>
	</joint>
	<joint name="jointfix_14_36" type="fixed">
		<parent link="link1_36"/>
		<child link="left-elbow"/>
		<dynamics damping="1.0" friction="0.0001"/>
		<origin rpy="0.00000 -0.00000 0.00000" xyz="0.00000 0.00000 0.00000"/>
		<axis xyz="0.00000 0.00000 0.00000"/>
	</joint>
	<joint name="right-hip-roll" type="revolute">
		<parent link="base"/>
		<child link="link1_38"/>
		<dynamics damping="1.0" friction="0.0001"/>
		<origin rpy="0.00000 -0.00000 0.00000" xyz="-0.00100 -0.09100 0.00000"/>
		<axis xyz="0.00000 0.00000 1.00000"/>
	</joint>
	<joint name="jointfix_31_38" type="fixed">
		<parent link="link1_38"/>
		<child link="right-hip-roll"/>
		<dynamics damping="1.0" friction="0.0001"/>
		<origin rpy="0.00000 -0.00000 0.00000" xyz="0.00000 0.00000 0.00000"/>
		<axis xyz="0.00000 0.00000 0.00000"/>
	</joint>
	<joint name="right-hip-yaw" type="revolute">
		<parent link="right-hip-roll"/>
		<child link="link1_40"/>
		<dynamics damping="1.0" friction="0.0001"/>
		<origin rpy="0.00000 -0.00000 0.00000" xyz="-0.05050 0.00000 0.04400"/>
		<axis xyz="0.00000 0.00000 1.00000"/>
	</joint>
	<joint name="jointfix_30_40" type="fixed">
		<parent link="link1_40"/>
		<child link="right-hip-yaw"/>
		<dynamics damping="1.0" friction="0.0001"/>
		<origin rpy="0.00000 -0.00000 0.00000" xyz="0.00000 0.00000 0.00000"/>
		<axis xyz="0.00000 0.00000 0.00000"/>
	</joint>
	<joint name="right-hip-pitch" type="revolute">
		<parent link="right-hip-yaw"/>
		<child link="link1_42"/>
		<dynamics damping="1.0" friction="0.0001"/>
		<origin rpy="0.00000 -0.00000 0.00000" xyz="0.00000 -0.00400 0.06800"/>
		<axis xyz="0.00000 0.00000 -1.00000"/>
	</joint>
	<joint name="jointfix_29_42" type="fixed">
		<parent link="link1_42"/>
		<child link="right-hip-pitch"/>
		<dynamics damping="1.0" friction="0.0001"/>
		<origin rpy="0.00000 -0.00000 0.00000" xyz="0.00000 0.00000 0.00000"/>
		<axis xyz="0.00000 0.00000 0.00000"/>
	</joint>
	<joint name="right-knee" type="revolute">
		<parent link="right-hip-pitch"/>
		<child link="link1_46"/>
		<dynamics damping="1.0" friction="0.0001"/>
		<origin rpy="0.00000 -0.00000 0.00000" xyz="0.12000 0.00000 0.00450"/>
		<axis xyz="0.00000 0.00000 1.00000"/>
	</joint>
	<joint name="jointfix_28_46" type="fixed">
		<parent link="link1_46"/>
		<child link="right-knee"/>
		<dynamics damping="1.0" friction="0.0001"/>
		<origin rpy="0.00000 -0.00000 0.00000" xyz="0.00000 0.00000 0.00000"/>
		<axis xyz="0.00000 0.00000 0.00000"/>
	</joint>
	<joint name="right-shin" type="continuous">
		<parent link="right-knee"/>
		<child link="link1_48"/>
		<dynamics damping="1.0" friction="0.0001"/>
		<origin rpy="0.00000 -0.00000 0.00000" xyz="0.06068 -0.04741 0.00000"/>
		<axis xyz="0.00000 0.00000 1.00000"/>
	</joint>
	<joint name="jointfix_27_48" type="fixed">
		<parent link="link1_48"/>
		<child link="right-shin"/>
		<dynamics damping="1.0" friction="0.0001"/>
		<origin rpy="0.00000 -0.00000 0.00000" xyz="0.00000 0.00000 0.00000"/>
		<axis xyz="0.00000 0.00000 0.00000"/>
	</joint>
	<joint name="right-tarsus" type="revolute">
		<parent link="right-shin"/>
		<child link="link1_50"/>
		<dynamics damping="1.0" friction="0.0001"/>
		<origin rpy="0.00000 -0.00000 0.00000" xyz="0.43476 -0.02000 0.00000"/>
		<axis xyz="0.00000 0.00000 1.00000"/>
	</joint>
	<joint name="jointfix_26_50" type="fixed">
		<parent link="link1_50"/>
		<child link="right-tarsus"/>
		<dynamics damping="1.0" friction="0.0001"/>
		<origin rpy="0.00000 -0.00000 0.00000" xyz="0.00000 0.00000 0.00000"/>
		<axis xyz="0.00000 0.00000 0.00000"/>
	</joint>
	<joint name="right-heel-spring" type="revolute">
		<parent link="right-tarsus"/>
		<child link="link1_52"/>
		<dynamics damping="1.0" friction="0.0001"/>
		<origin rpy="0.00000 -0.00000 0.00000" xyz="-0.01766 0.02946 0.00104"/>
		<axis xyz="0.00000 0.00000 1.00000"/>
	</joint>
	<joint name="jointfix_19_52" type="fixed">
		<parent link="link1_52"/>
		<child link="right-heel-spring"/>
		<dynamics damping="1.0" friction="0.0001"/>
		<origin rpy="0.00000 -0.00000 0.00000" xyz="0.00000 0.00000 0.00000"/>
		<axis xyz="0.00000 0.00000 0.00000"/>
	</joint>
	<joint name="right-toe-A" type="revolute">
		<parent link="right-tarsus"/>
		<child link="link1_54"/>
		<dynamics damping="1.0" friction="0.0001"/>
		<origin rpy="0.00000 -0.00000 0.00000" xyz="0.05900 0.03400 -0.02760"/>
		<axis xyz="0.00000 0.00000 1.00000"/>
	</joint>
	<joint name="jointfix_21_54" type="fixed">
		<parent link="link1_54"/>
		<child link="right-toe-A"/>
		<dynamics damping="1.0" friction="0.0001"/>
		<origin rpy="0.00000 -0.00000 0.00000" xyz="0.00000 0.00000 0.00000"/>
		<axis xyz="0.00000 0.00000 0.00000"/>
	</joint>
	<joint name="right-toe-B" type="revolute">
		<parent link="right-tarsus"/>
		<child link="link1_58"/>
		<dynamics damping="1.0" friction="0.0001"/>
		<origin rpy="0.00000 -0.00000 0.00000" xyz="0.11100 0.03400 0.02760"/>
		<axis xyz="0.00000 0.00000 1.00000"/>
	</joint>
	<joint name="jointfix_23_58" type="fixed">
		<parent link="link1_58"/>
		<child link="right-toe-B"/>
		<dynamics damping="1.0" friction="0.0001"/>
		<origin rpy="0.00000 -0.00000 0.00000" xyz="0.00000 0.00000 0.00000"/>
		<axis xyz="0.00000 0.00000 0.00000"/>
	</joint>
	<joint name="right-toe-pitch" type="revolute">
		<parent link="right-tarsus"/>
		<child link="link1_62"/>
		<dynamics damping="1.0" friction="0.0001"/>
		<origin rpy="0.00000 -0.00000 0.00000" xyz="0.40800 0.04000 0.00000"/>
		<axis xyz="0.00000 0.00000 1.00000"/>
	</joint>
	<joint name="jointfix_25_62" type="fixed">
		<parent link="link1_62"/>
		<child link="right-toe-pitch"/>
		<dynamics damping="1.0" friction="0.0001"/>
		<origin rpy="0.00000 -0.00000 0.00000" xyz="0.00000 0.00000 0.00000"/>
		<axis xyz="0.00000 0.00000 0.00000"/>
	</joint>
	<joint name="right-toe-roll" type="revolute">
		<parent link="right-toe-pitch"/>
		<child link="link1_64"/>
		<dynamics damping="1.0" friction="0.0001"/>
		<origin rpy="0.00000 -0.00000 0.00000" xyz="0.00000 0.00000 0.00000"/>
		<axis xyz="0.00000 0.00000 1.00000"/>
	</joint>
	<joint name="jointfix_24_64" type="fixed">
		<parent link="link1_64"/>
		<child link="right-toe-roll"/>
		<dynamics damping="1.0" friction="0.0001"/>
		<origin rpy="0.00000 -0.00000 0.00000" xyz="0.00000 0.00000 0.00000"/>
		<axis xyz="0.00000 0.00000 0.00000"/>
	</joint>
	<joint name="right-shoulder-roll" type="revolute">
		<parent link="base"/>
		<child link="link1_66"/>
		<dynamics damping="1.0" friction="0.0001"/>
		<origin rpy="0.00000 -0.00000 0.00000" xyz="-0.00100 -0.12000 0.40000"/>
		<axis xyz="0.00000 0.00000 1.00000"/>
	</joint>
	<joint name="jointfix_35_66" type="fixed">
		<parent link="link1_66"/>
		<child link="right-shoulder-roll"/>
		<dynamics damping="1.0" friction="0.0001"/>
		<origin rpy="0.00000 -0.00000 0.00000" xyz="0.00000 0.00000 0.00000"/>
		<axis xyz="0.00000 0.00000 0.00000"/>
	</joint>
	<joint name="right-shoulder-pitch" type="revolute">
		<parent link="right-shoulder-roll"/>
		<child link="link1_68"/>
		<dynamics damping="1.0" friction="0.0001"/>
		<origin rpy="0.00000 -0.00000 0.00000" xyz="-0.00317 0.01106 0.05550"/>
		<axis xyz="0.00000 0.00000 -1.00000"/>
	</joint>
	<joint name="jointfix_34_68" type="fixed">
		<parent link="link1_68"/>
		<child link="right-shoulder-pitch"/>
		<dynamics damping="1.0" friction="0.0001"/>
		<origin rpy="0.00000 -0.00000 0.00000" xyz="0.00000 0.00000 0.00000"/>
		<axis xyz="0.00000 0.00000 0.00000"/>
	</joint>
	<joint name="right-shoulder-yaw" type="revolute">
		<parent link="right-shoulder-pitch"/>
		<child link="link1_70"/>
		<dynamics damping="1.0" friction="0.0001"/>
		<origin rpy="0.00000 -0.00000 0.00000" xyz="0.00000 0.16500 -0.10000"/>
		<axis xyz="0.00000 0.00000 1.00000"/>
	</joint>
	<joint name="jointfix_33_70" type="fixed">
		<parent link="link1_70"/>
		<child link="right-shoulder-yaw"/>
		<dynamics damping="1.0" friction="0.0001"/>
		<origin rpy="0.00000 -0.00000 0.00000" xyz="0.00000 0.00000 0.00000"/>
		<axis xyz="0.00000 0.00000 0.00000"/>
	</joint>
	<joint name="right-elbow" type="revolute">
		<parent link="right-shoulder-yaw"/>
		<child link="link1_72"/>
		<dynamics damping="1.0" friction="0.0001"/>
		<origin rpy="0.00000 -0.00000 0.00000" xyz="0.00000 0.03850 0.18500"/>
		<axis xyz="0.00000 0.00000 1.00000"/>
	</joint>
	<joint name="jointfix_32_72" type="fixed">
		<parent link="link1_72"/>
		<child link="right-elbow"/>
		<dynamics damping="1.0" friction="0.0001"/>
		<origin rpy="0.00000 -0.00000 0.00000" xyz="0.00000 0.00000 0.00000"/>
		<axis xyz="0.00000 0.00000 0.00000"/>
	</joint>
</robot>
